Workbook

Sheet DASHBOARD
A1: LAB OPERATIONS DASHBOARD
A2: =" Viewing: "&SELECTIONS!B4&" · "&SELECTIONS!B5&" · "&SELECTIONS!B6&" · "&SELECTIONS!B7 -> Viewing: January · Week 1 · All Sites · All Departments
A3: ⟵ Go to SELECTIONS sheet to change filters · Go to DATA ENTRY sheet to add data
B5: TOTAL TESTS RUN | E5: UNIQUE REQ NUMBERS | H5: TAT % vs 90% TARGET | K5: STAFF ADEQUACY | M5: ANALYZER STATUS
B6: =A50 -> 12465 | E6: =A51 -> 11599 | H6: =A52 -> 0.86777778 | K6: =A68 -> 0.51851852 | M6: =A72 -> 1
B7: =IF(A55=0,"No prior week data",IF((A50-A55)>0,"▲ +"&TEXT(ABS((A50-A55)),"#,##0")&" vs prev week",IF((A50-A55)<0,"▼ -"&TEXT(ABS((A50-A55)),"#,##0")&" vs prev week","► No change vs prev week"))) -> No prior week data | E7: =IF(A56=0,"No prior week data",IF((A51-A56)>0,"▲ +"&TEXT(ABS((A51-A56)),"#,##0")&" vs prev week",IF((A51-A56)<0,"▼ -"&TEXT(ABS((A51-A56)),"#,##0")&" vs prev week","► No change vs prev week"))) -> No prior week data | H7: =IF(A57=0,"No prior week data",IF((A52-A57)>0,"▲ +"&TEXT(ABS((A52-A57)),"0.0%")&" vs prev week",IF((A52-A57)<0,"▼ -"&TEXT(ABS((A52-A57)),"0.0%")&" vs prev week","► No change vs prev week"))) -> No prior week data | K7: =IF(A68=1,"✓ 100% Depts Fully Staffed","⚠ "&TEXT(A68,"0%")&" staffed | Gap: "&TEXT(A69,"+0%;-0%;0%")) -> ⚠ 52% staffed | Gap: -48% | M7: =IF(A72=0,"No data","⚠ "&TEXT(A72,"0.0%")&" Avg Avail | Gap: "&TEXT(A73,"+0.0%;-0.0%;0.0%")&" vs 90%") -> ⚠ 100.0% Avg Avail | Gap: +10.0% vs 90%
B8: Month Total | E8: Month Total | H8: Month TAT / Gap vs 90% | K8: Understaffed Depts / Total Shortfall | M8: Functional / Down / For Repair
B9: =A58 -> 12465 | E9: =A59 -> 11599 | H9: =TEXT(A60,"0.0%")&" / "&TEXT(A60-0.9,"+0.0%;-0.0%;0.0%") -> 86.8% / -3.2% | K9: =A70&" dept(s) | "&A71&" staff short" -> 26 dept(s) | 58 staff short | M9: =H27&" ✓ | "&H28&" ↓ | "&H29&" 🔧" -> 18 ✓ | 0 ↓ | 0 🔧
B12: TESTS BY SITE | H12: TESTS BY DEPARTMENT
B13: Site | C13: Tests | D13: REQs | E13: TAT % | F13: Staff Gap | G13: Status | H13: Department | I13: Tests | J13: REQs | K13: TAT % | L13: Gap vs 90%
B14: Site A | C14: =SUMIFS('DATA ENTRY'!F6:F500,'DATA ENTRY'!B6:B500,SELECTIONS!E3,'DATA ENTRY'!C6:C500,SELECTIONS!E4,'DATA ENTRY'!D6:D500,"Site A",'DATA ENTRY'!E6:E500,SELECTIONS!E6) -> 1532 | D14: =SUMIFS('DATA ENTRY'!G6:G500,'DATA ENTRY'!B6:B500,SELECTIONS!E3,'DATA ENTRY'!C6:C500,SELECTIONS!E4,'DATA ENTRY'!D6:D500,"Site A",'DATA ENTRY'!E6:E500,SELECTIONS!E6) -> 761 | E14: =IFERROR(AVERAGEIFS('DATA ENTRY'!H6:H500,'DATA ENTRY'!H6:H500,">0",'DATA ENTRY'!B6:B500,SELECTIONS!E3,'DATA ENTRY'!C6:C500,SELECTIONS!E4,'DATA ENTRY'!D6:D500,"Site A",'DATA ENTRY'!E6:E500,SELECTIONS!E6),0) -> 0.88166667 | F14: =SUMIFS('DATA ENTRY'!G88:G264,'DATA ENTRY'!A88:A264,"Site A",'DATA ENTRY'!B88:B264,SELECTIONS!E6,'DATA ENTRY'!C88:C264,SELECTIONS!E3,'DATA ENTRY'!D88:D264,SELECTIONS!E4) -> 1 | G14: =IF(IFERROR(AVERAGEIFS('DATA ENTRY'!H6:H500,'DATA ENTRY'!H6:H500,">0",'DATA ENTRY'!B6:B500,SELECTIONS!E3,'DATA ENTRY'!C6:C500,SELECTIONS!E4,'DATA ENTRY'!D6:D500,"Site A",'DATA ENTRY'!E6:E500,SELECTIONS!E6),0)>=0.9,"✓ On Target","⚠ Below Target") -> ⚠ Below Target | H14: Chemistry | I14: =SUMIFS('DATA ENTRY'!F6:F500,'DATA ENTRY'!B6:B500,SELECTIONS!E3,'DATA ENTRY'!C6:C500,SELECTIONS!E4,'DATA ENTRY'!D6:D500,SELECTIONS!E5,'DATA ENTRY'!E6:E500,"Chemistry") -> 2275 | J14: =SUMIFS('DATA ENTRY'!G6:G500,'DATA ENTRY'!B6:B500,SELECTIONS!E3,'DATA ENTRY'!C6:C500,SELECTIONS!E4,'DATA ENTRY'!D6:D500,SELECTIONS!E5,'DATA ENTRY'!E6:E500,"Chemistry") -> 1561 | K14: =IFERROR(AVERAGEIFS('DATA ENTRY'!H6:H500,'DATA ENTRY'!H6:H500,">0",'DATA ENTRY'!B6:B500,SELECTIONS!E3,'DATA ENTRY'!C6:C500,SELECTIONS!E4,'DATA ENTRY'!D6:D500,SELECTIONS!E5,'DATA ENTRY'!E6:E500,"Chemistry"),0) -> 0.87888889 | L14: =IFERROR(AVERAGEIFS('DATA ENTRY'!H6:H500,'DATA ENTRY'!H6:H500,">0",'DATA ENTRY'!B6:B500,SELECTIONS!E3,'DATA ENTRY'!C6:C500,SELECTIONS!E4,'DATA ENTRY'!D6:D500,SELECTIONS!E5,'DATA ENTRY'!E6:E500,"Chemistry"),0)-0.9 -> -0.021111111
B15: Site B | C15: =SUMIFS('DATA ENTRY'!F6:F500,'DATA ENTRY'!B6:B500,SELECTIONS!E3,'DATA ENTRY'!C6:C500,SELECTIONS!E4,'DATA ENTRY'!D6:D500,"Site B",'DATA ENTRY'!E6:E500,SELECTIONS!E6) -> 1468 | D15: =SUMIFS('DATA ENTRY'!G6:G500,'DATA ENTRY'!B6:B500,SELECTIONS!E3,'DATA ENTRY'!C6:C500,SELECTIONS!E4,'DATA ENTRY'!D6:D500,"Site B",'DATA ENTRY'!E6:E500,SELECTIONS!E6) -> 1321 | E15: =IFERROR(AVERAGEIFS('DATA ENTRY'!H6:H500,'DATA ENTRY'!H6:H500,">0",'DATA ENTRY'!B6:B500,SELECTIONS!E3,'DATA ENTRY'!C6:C500,SELECTIONS!E4,'DATA ENTRY'!D6:D500,"Site B",'DATA ENTRY'!E6:E500,SELECTIONS!E6),0) -> 0.85166667 | F15: =SUMIFS('DATA ENTRY'!G88:G264,'DATA ENTRY'!A88:A264,"Site B",'DATA ENTRY'!B88:B264,SELECTIONS!E6,'DATA ENTRY'!C88:C264,SELECTIONS!E3,'DATA ENTRY'!D88:D264,SELECTIONS!E4) -> -3 | G15: =IF(IFERROR(AVERAGEIFS('DATA ENTRY'!H6:H500,'DATA ENTRY'!H6:H500,">0",'DATA ENTRY'!B6:B500,SELECTIONS!E3,'DATA ENTRY'!C6:C500,SELECTIONS!E4,'DATA ENTRY'!D6:D500,"Site B",'DATA ENTRY'!E6:E500,SELECTIONS!E6),0)>=0.9,"✓ On Target","⚠ Below Target") -> ⚠ Below Target | H15: Serology | I15: =SUMIFS('DATA ENTRY'!F6:F500,'DATA ENTRY'!B6:B500,SELECTIONS!E3,'DATA ENTRY'!C6:C500,SELECTIONS!E4,'DATA ENTRY'!D6:D500,SELECTIONS!E5,'DATA ENTRY'!E6:E500,"Serology") -> 1824 | J15: =SUMIFS('DATA ENTRY'!G6:G500,'DATA ENTRY'!B6:B500,SELECTIONS!E3,'DATA ENTRY'!C6:C500,SELECTIONS!E4,'DATA ENTRY'!D6:D500,SELECTIONS!E5,'DATA ENTRY'!E6:E500,"Serology") -> 2096 | K15: =IFERROR(AVERAGEIFS('DATA ENTRY'!H6:H500,'DATA ENTRY'!H6:H500,">0",'DATA ENTRY'!B6:B500,SELECTIONS!E3,'DATA ENTRY'!C6:C500,SELECTIONS!E4,'DATA ENTRY'!D6:D500,SELECTIONS!E5,'DATA ENTRY'!E6:E500,"Serology"),0) -> 0.86222222 | L15: =IFERROR(AVERAGEIFS('DATA ENTRY'!H6:H500,'DATA ENTRY'!H6:H500,">0",'DATA ENTRY'!B6:B500,SELECTIONS!E3,'DATA ENTRY'!C6:C500,SELECTIONS!E4,'DATA ENTRY'!D6:D500,SELECTIONS!E5,'DATA ENTRY'!E6:E500,"Serology"),0)-0.9 -> -0.037777778
B16: Site C | C16: =SUMIFS('DATA ENTRY'!F6:F500,'DATA ENTRY'!B6:B500,SELECTIONS!E3,'DATA ENTRY'!C6:C500,SELECTIONS!E4,'DATA ENTRY'!D6:D500,"Site C",'DATA ENTRY'!E6:E500,SELECTIONS!E6) -> 1232 | D16: =SUMIFS('DATA ENTRY'!G6:G500,'DATA ENTRY'!B6:B500,SELECTIONS!E3,'DATA ENTRY'!C6:C500,SELECTIONS!E4,'DATA ENTRY'!D6:D500,"Site C",'DATA ENTRY'!E6:E500,SELECTIONS!E6) -> 1144 | E16: =IFERROR(AVERAGEIFS('DATA ENTRY'!H6:H500,'DATA ENTRY'!H6:H500,">0",'DATA ENTRY'!B6:B500,SELECTIONS!E3,'DATA ENTRY'!C6:C500,SELECTIONS!E4,'DATA ENTRY'!D6:D500,"Site C",'DATA ENTRY'!E6:E500,SELECTIONS!E6),0) -> 0.90333333 | F16: =SUMIFS('DATA ENTRY'!G88:G264,'DATA ENTRY'!A88:A264,"Site C",'DATA ENTRY'!B88:B264,SELECTIONS!E6,'DATA ENTRY'!C88:C264,SELECTIONS!E3,'DATA ENTRY'!D88:D264,SELECTIONS!E4) -> -6 | G16: =IF(IFERROR(AVERAGEIFS('DATA ENTRY'!H6:H500,'DATA ENTRY'!H6:H500,">0",'DATA ENTRY'!B6:B500,SELECTIONS!E3,'DATA ENTRY'!C6:C500,SELECTIONS!E4,'DATA ENTRY'!D6:D500,"Site C",'DATA ENTRY'!E6:E500,SELECTIONS!E6),0)>=0.9,"✓ On Target","⚠ Below Target") -> ✓ On Target | H16: Hematology | I16: =SUMIFS('DATA ENTRY'!F6:F500,'DATA ENTRY'!B6:B500,SELECTIONS!E3,'DATA ENTRY'!C6:C500,SELECTIONS!E4,'DATA ENTRY'!D6:D500,SELECTIONS!E5,'DATA ENTRY'!E6:E500,"Hematology") -> 1717 | J16: =SUMIFS('DATA ENTRY'!G6:G500,'DATA ENTRY'!B6:B500,SELECTIONS!E3,'DATA ENTRY'!C6:C500,SELECTIONS!E4,'DATA ENTRY'!D6:D500,SELECTIONS!E5,'DATA ENTRY'!E6:E500,"Hematology") -> 1744 | K16: =IFERROR(AVERAGEIFS('DATA ENTRY'!H6:H500,'DATA ENTRY'!H6:H500,">0",'DATA ENTRY'!B6:B500,SELECTIONS!E3,'DATA ENTRY'!C6:C500,SELECTIONS!E4,'DATA ENTRY'!D6:D500,SELECTIONS!E5,'DATA ENTRY'!E6:E500,"Hematology"),0) -> 0.88333333 | L16: =IFERROR(AVERAGEIFS('DATA ENTRY'!H6:H500,'DATA ENTRY'!H6:H500,">0",'DATA ENTRY'!B6:B500,SELECTIONS!E3,'DATA ENTRY'!C6:C500,SELECTIONS!E4,'DATA ENTRY'!D6:D500,SELECTIONS!E5,'DATA ENTRY'!E6:E500,"Hematology"),0)-0.9 -> -0.016666667
B17: Site D | C17: =SUMIFS('DATA ENTRY'!F6:F500,'DATA ENTRY'!B6:B500,SELECTIONS!E3,'DATA ENTRY'!C6:C500,SELECTIONS!E4,'DATA ENTRY'!D6:D500,"Site D",'DATA ENTRY'!E6:E500,SELECTIONS!E6) -> 1519 | D17: =SUMIFS('DATA ENTRY'!G6:G500,'DATA ENTRY'!B6:B500,SELECTIONS!E3,'DATA ENTRY'!C6:C500,SELECTIONS!E4,'DATA ENTRY'!D6:D500,"Site D",'DATA ENTRY'!E6:E500,SELECTIONS!E6) -> 1205 | E17: =IFERROR(AVERAGEIFS('DATA ENTRY'!H6:H500,'DATA ENTRY'!H6:H500,">0",'DATA ENTRY'!B6:B500,SELECTIONS!E3,'DATA ENTRY'!C6:C500,SELECTIONS!E4,'DATA ENTRY'!D6:D500,"Site D",'DATA ENTRY'!E6:E500,SELECTIONS!E6),0) -> 0.85 | F17: =SUMIFS('DATA ENTRY'!G88:G264,'DATA ENTRY'!A88:A264,"Site D",'DATA ENTRY'!B88:B264,SELECTIONS!E6,'DATA ENTRY'!C88:C264,SELECTIONS!E3,'DATA ENTRY'!D88:D264,SELECTIONS!E4) -> -5 | G17: =IF(IFERROR(AVERAGEIFS('DATA ENTRY'!H6:H500,'DATA ENTRY'!H6:H500,">0",'DATA ENTRY'!B6:B500,SELECTIONS!E3,'DATA ENTRY'!C6:C500,SELECTIONS!E4,'DATA ENTRY'!D6:D500,"Site D",'DATA ENTRY'!E6:E500,SELECTIONS!E6),0)>=0.9,"✓ On Target","⚠ Below Target") -> ⚠ Below Target | H17: Cardiac Markers | I17: =SUMIFS('DATA ENTRY'!F6:F500,'DATA ENTRY'!B6:B500,SELECTIONS!E3,'DATA ENTRY'!C6:C500,SELECTIONS!E4,'DATA ENTRY'!D6:D500,SELECTIONS!E5,'DATA ENTRY'!E6:E500,"Cardiac Markers") -> 2016 | J17: =SUMIFS('DATA ENTRY'!G6:G500,'DATA ENTRY'!B6:B500,SELECTIONS!E3,'DATA ENTRY'!C6:C500,SELECTIONS!E4,'DATA ENTRY'!D6:D500,SELECTIONS!E5,'DATA ENTRY'!E6:E500,"Cardiac Markers") -> 1828 | K17: =IFERROR(AVERAGEIFS('DATA ENTRY'!H6:H500,'DATA ENTRY'!H6:H500,">0",'DATA ENTRY'!B6:B500,SELECTIONS!E3,'DATA ENTRY'!C6:C500,SELECTIONS!E4,'DATA ENTRY'!D6:D500,SELECTIONS!E5,'DATA ENTRY'!E6:E500,"Cardiac Markers"),0) -> 0.88222222 | L17: =IFERROR(AVERAGEIFS('DATA ENTRY'!H6:H500,'DATA ENTRY'!H6:H500,">0",'DATA ENTRY'!B6:B500,SELECTIONS!E3,'DATA ENTRY'!C6:C500,SELECTIONS!E4,'DATA ENTRY'!D6:D500,SELECTIONS!E5,'DATA ENTRY'!E6:E500,"Cardiac Markers"),0)-0.9 -> -0.017777778
B18: Site E | C18: =SUMIFS('DATA ENTRY'!F6:F500,'DATA ENTRY'!B6:B500,SELECTIONS!E3,'DATA ENTRY'!C6:C500,SELECTIONS!E4,'DATA ENTRY'!D6:D500,"Site E",'DATA ENTRY'!E6:E500,SELECTIONS!E6) -> 1633 | D18: =SUMIFS('DATA ENTRY'!G6:G500,'DATA ENTRY'!B6:B500,SELECTIONS!E3,'DATA ENTRY'!C6:C500,SELECTIONS!E4,'DATA ENTRY'!D6:D500,"Site E",'DATA ENTRY'!E6:E500,SELECTIONS!E6) -> 1815 | E18: =IFERROR(AVERAGEIFS('DATA ENTRY'!H6:H500,'DATA ENTRY'!H6:H500,">0",'DATA ENTRY'!B6:B500,SELECTIONS!E3,'DATA ENTRY'!C6:C500,SELECTIONS!E4,'DATA ENTRY'!D6:D500,"Site E",'DATA ENTRY'!E6:E500,SELECTIONS!E6),0) -> 0.86 | F18: =SUMIFS('DATA ENTRY'!G88:G264,'DATA ENTRY'!A88:A264,"Site E",'DATA ENTRY'!B88:B264,SELECTIONS!E6,'DATA ENTRY'!C88:C264,SELECTIONS!E3,'DATA ENTRY'!D88:D264,SELECTIONS!E4) -> -5 | G18: =IF(IFERROR(AVERAGEIFS('DATA ENTRY'!H6:H500,'DATA ENTRY'!H6:H500,">0",'DATA ENTRY'!B6:B500,SELECTIONS!E3,'DATA ENTRY'!C6:C500,SELECTIONS!E4,'DATA ENTRY'!D6:D500,"Site E",'DATA ENTRY'!E6:E500,SELECTIONS!E6),0)>=0.9,"✓ On Target","⚠ Below Target") -> ⚠ Below Target | H18: Endocrinology | I18: =SUMIFS('DATA ENTRY'!F6:F500,'DATA ENTRY'!B6:B500,SELECTIONS!E3,'DATA ENTRY'!C6:C500,SELECTIONS!E4,'DATA ENTRY'!D6:D500,SELECTIONS!E5,'DATA ENTRY'!E6:E500,"Endocrinology") -> 2170 | J18: =SUMIFS('DATA ENTRY'!G6:G500,'DATA ENTRY'!B6:B500,SELECTIONS!E3,'DATA ENTRY'!C6:C500,SELECTIONS!E4,'DATA ENTRY'!D6:D500,SELECTIONS!E5,'DATA ENTRY'!E6:E500,"Endocrinology") -> 2213 | K18: =IFERROR(AVERAGEIFS('DATA ENTRY'!H6:H500,'DATA ENTRY'!H6:H500,">0",'DATA ENTRY'!B6:B500,SELECTIONS!E3,'DATA ENTRY'!C6:C500,SELECTIONS!E4,'DATA ENTRY'!D6:D500,SELECTIONS!E5,'DATA ENTRY'!E6:E500,"Endocrinology"),0) -> 0.85555556 | L18: =IFERROR(AVERAGEIFS('DATA ENTRY'!H6:H500,'DATA ENTRY'!H6:H500,">0",'DATA ENTRY'!B6:B500,SELECTIONS!E3,'DATA ENTRY'!C6:C500,SELECTIONS!E4,'DATA ENTRY'!D6:D500,SELECTIONS!E5,'DATA ENTRY'!E6:E500,"Endocrinology"),0)-0.9 -> -0.044444444
B19: Site F | C19: =SUMIFS('DATA ENTRY'!F6:F500,'DATA ENTRY'!B6:B500,SELECTIONS!E3,'DATA ENTRY'!C6:C500,SELECTIONS!E4,'DATA ENTRY'!D6:D500,"Site F",'DATA ENTRY'!E6:E500,SELECTIONS!E6) -> 1148 | D19: =SUMIFS('DATA ENTRY'!G6:G500,'DATA ENTRY'!B6:B500,SELECTIONS!E3,'DATA ENTRY'!C6:C500,SELECTIONS!E4,'DATA ENTRY'!D6:D500,"Site F",'DATA ENTRY'!E6:E500,SELECTIONS!E6) -> 1711 | E19: =IFERROR(AVERAGEIFS('DATA ENTRY'!H6:H500,'DATA ENTRY'!H6:H500,">0",'DATA ENTRY'!B6:B500,SELECTIONS!E3,'DATA ENTRY'!C6:C500,SELECTIONS!E4,'DATA ENTRY'!D6:D500,"Site F",'DATA ENTRY'!E6:E500,SELECTIONS!E6),0) -> 0.84833333 | F19: =SUMIFS('DATA ENTRY'!G88:G264,'DATA ENTRY'!A88:A264,"Site F",'DATA ENTRY'!B88:B264,SELECTIONS!E6,'DATA ENTRY'!C88:C264,SELECTIONS!E3,'DATA ENTRY'!D88:D264,SELECTIONS!E4) -> -9 | G19: =IF(IFERROR(AVERAGEIFS('DATA ENTRY'!H6:H500,'DATA ENTRY'!H6:H500,">0",'DATA ENTRY'!B6:B500,SELECTIONS!E3,'DATA ENTRY'!C6:C500,SELECTIONS!E4,'DATA ENTRY'!D6:D500,"Site F",'DATA ENTRY'!E6:E500,SELECTIONS!E6),0)>=0.9,"✓ On Target","⚠ Below Target") -> ⚠ Below Target | H19: Toxicology | I19: =SUMIFS('DATA ENTRY'!F6:F500,'DATA ENTRY'!B6:B500,SELECTIONS!E3,'DATA ENTRY'!C6:C500,SELECTIONS!E4,'DATA ENTRY'!D6:D500,SELECTIONS!E5,'DATA ENTRY'!E6:E500,"Toxicology") -> 2463 | J19: =SUMIFS('DATA ENTRY'!G6:G500,'DATA ENTRY'!B6:B500,SELECTIONS!E3,'DATA ENTRY'!C6:C500,SELECTIONS!E4,'DATA ENTRY'!D6:D500,SELECTIONS!E5,'DATA ENTRY'!E6:E500,"Toxicology") -> 2157 | K19: =IFERROR(AVERAGEIFS('DATA ENTRY'!H6:H500,'DATA ENTRY'!H6:H500,">0",'DATA ENTRY'!B6:B500,SELECTIONS!E3,'DATA ENTRY'!C6:C500,SELECTIONS!E4,'DATA ENTRY'!D6:D500,SELECTIONS!E5,'DATA ENTRY'!E6:E500,"Toxicology"),0) -> 0.84444444 | L19: =IFERROR(AVERAGEIFS('DATA ENTRY'!H6:H500,'DATA ENTRY'!H6:H500,">0",'DATA ENTRY'!B6:B500,SELECTIONS!E3,'DATA ENTRY'!C6:C500,SELECTIONS!E4,'DATA ENTRY'!D6:D500,SELECTIONS!E5,'DATA ENTRY'!E6:E500,"Toxicology"),0)-0.9 -> -0.055555556
B20: Site G | C20: =SUMIFS('DATA ENTRY'!F6:F500,'DATA ENTRY'!B6:B500,SELECTIONS!E3,'DATA ENTRY'!C6:C500,SELECTIONS!E4,'DATA ENTRY'!D6:D500,"Site G",'DATA ENTRY'!E6:E500,SELECTIONS!E6) -> 1053 | D20: =SUMIFS('DATA ENTRY'!G6:G500,'DATA ENTRY'!B6:B500,SELECTIONS!E3,'DATA ENTRY'!C6:C500,SELECTIONS!E4,'DATA ENTRY'!D6:D500,"Site G",'DATA ENTRY'!E6:E500,SELECTIONS!E6) -> 1263 | E20: =IFERROR(AVERAGEIFS('DATA ENTRY'!H6:H500,'DATA ENTRY'!H6:H500,">0",'DATA ENTRY'!B6:B500,SELECTIONS!E3,'DATA ENTRY'!C6:C500,SELECTIONS!E4,'DATA ENTRY'!D6:D500,"Site G",'DATA ENTRY'!E6:E500,SELECTIONS!E6),0) -> 0.89 | F20: =SUMIFS('DATA ENTRY'!G88:G264,'DATA ENTRY'!A88:A264,"Site G",'DATA ENTRY'!B88:B264,SELECTIONS!E6,'DATA ENTRY'!C88:C264,SELECTIONS!E3,'DATA ENTRY'!D88:D264,SELECTIONS!E4) -> -6 | G20: =IF(IFERROR(AVERAGEIFS('DATA ENTRY'!H6:H500,'DATA ENTRY'!H6:H500,">0",'DATA ENTRY'!B6:B500,SELECTIONS!E3,'DATA ENTRY'!C6:C500,SELECTIONS!E4,'DATA ENTRY'!D6:D500,"Site G",'DATA ENTRY'!E6:E500,SELECTIONS!E6),0)>=0.9,"✓ On Target","⚠ Below Target") -> ⚠ Below Target
B21: Site H | C21: =SUMIFS('DATA ENTRY'!F6:F500,'DATA ENTRY'!B6:B500,SELECTIONS!E3,'DATA ENTRY'!C6:C500,SELECTIONS!E4,'DATA ENTRY'!D6:D500,"Site H",'DATA ENTRY'!E6:E500,SELECTIONS!E6) -> 1341 | D21: =SUMIFS('DATA ENTRY'!G6:G500,'DATA ENTRY'!B6:B500,SELECTIONS!E3,'DATA ENTRY'!C6:C500,SELECTIONS!E4,'DATA ENTRY'!D6:D500,"Site H",'DATA ENTRY'!E6:E500,SELECTIONS!E6) -> 1362 | E21: =IFERROR(AVERAGEIFS('DATA ENTRY'!H6:H500,'DATA ENTRY'!H6:H500,">0",'DATA ENTRY'!B6:B500,SELECTIONS!E3,'DATA ENTRY'!C6:C500,SELECTIONS!E4,'DATA ENTRY'!D6:D500,"Site H",'DATA ENTRY'!E6:E500,SELECTIONS!E6),0) -> 0.88833333 | F21: =SUMIFS('DATA ENTRY'!G88:G264,'DATA ENTRY'!A88:A264,"Site H",'DATA ENTRY'!B88:B264,SELECTIONS!E6,'DATA ENTRY'!C88:C264,SELECTIONS!E3,'DATA ENTRY'!D88:D264,SELECTIONS!E4) -> -8 | G21: =IF(IFERROR(AVERAGEIFS('DATA ENTRY'!H6:H500,'DATA ENTRY'!H6:H500,">0",'DATA ENTRY'!B6:B500,SELECTIONS!E3,'DATA ENTRY'!C6:C500,SELECTIONS!E4,'DATA ENTRY'!D6:D500,"Site H",'DATA ENTRY'!E6:E500,SELECTIONS!E6),0)>=0.9,"✓ On Target","⚠ Below Target") -> ⚠ Below Target
B22: Site I | C22: =SUMIFS('DATA ENTRY'!F6:F500,'DATA ENTRY'!B6:B500,SELECTIONS!E3,'DATA ENTRY'!C6:C500,SELECTIONS!E4,'DATA ENTRY'!D6:D500,"Site I",'DATA ENTRY'!E6:E500,SELECTIONS!E6) -> 1539 | D22: =SUMIFS('DATA ENTRY'!G6:G500,'DATA ENTRY'!B6:B500,SELECTIONS!E3,'DATA ENTRY'!C6:C500,SELECTIONS!E4,'DATA ENTRY'!D6:D500,"Site I",'DATA ENTRY'!E6:E500,SELECTIONS!E6) -> 1017 | E22: =IFERROR(AVERAGEIFS('DATA ENTRY'!H6:H500,'DATA ENTRY'!H6:H500,">0",'DATA ENTRY'!B6:B500,SELECTIONS!E3,'DATA ENTRY'!C6:C500,SELECTIONS!E4,'DATA ENTRY'!D6:D500,"Site I",'DATA ENTRY'!E6:E500,SELECTIONS!E6),0) -> 0.83666667 | F22: =SUMIFS('DATA ENTRY'!G88:G264,'DATA ENTRY'!A88:A264,"Site I",'DATA ENTRY'!B88:B264,SELECTIONS!E6,'DATA ENTRY'!C88:C264,SELECTIONS!E3,'DATA ENTRY'!D88:D264,SELECTIONS!E4) -> 2 | G22: =IF(IFERROR(AVERAGEIFS('DATA ENTRY'!H6:H500,'DATA ENTRY'!H6:H500,">0",'DATA ENTRY'!B6:B500,SELECTIONS!E3,'DATA ENTRY'!C6:C500,SELECTIONS!E4,'DATA ENTRY'!D6:D500,"Site I",'DATA ENTRY'!E6:E500,SELECTIONS!E6),0)>=0.9,"✓ On Target","⚠ Below Target") -> ⚠ Below Target
B25: STAFFING OVERSite BEW (Target: 6 staff per site) | G25: ANALYZER STATUS (Filtered by Month, Week, Site & Dept)
B26: Site | C26: Actual Staff | D26: Target | E26: Gap | F26: Status | G26: Status | H26: Count | I26: % of Total | J26: Avg % Avail | K26: Gap vs 90%
B27: Site A | C27: =IFERROR(AVERAGEIFS('DATA ENTRY'!E88:E264,'DATA ENTRY'!E88:E264,">0",'DATA ENTRY'!A88:A264,"Site A",'DATA ENTRY'!B88:B264,SELECTIONS!E6,'DATA ENTRY'!C88:C264,SELECTIONS!E3,'DATA ENTRY'!D88:D264,SELECTIONS!E4),0) -> 6.1666667 | D27: 6 | E27: =C27-D27 -> 0.16666667 | F27: =IF(C27>=D27,"✓ Staffed","⚠ Gap") -> ✓ Staffed | G27: Functional | H27: =COUNTIFS('DATA ENTRY'!E66:E264,"Functional",'DATA ENTRY'!A66:A264,SELECTIONS!E5,'DATA ENTRY'!B66:B264,SELECTIONS!E6,'DATA ENTRY'!M66:M264,SELECTIONS!E3,'DATA ENTRY'!N66:N264,SELECTIONS!E4) -> 18 | I27: =IFERROR(H27/(H27+H28+H29),0) -> 1 | J27: =IFERROR(AVERAGEIFS('DATA ENTRY'!K66:K264,'DATA ENTRY'!E66:E264,"Functional",'DATA ENTRY'!A66:A264,SELECTIONS!E5,'DATA ENTRY'!B66:B264,SELECTIONS!E6,'DATA ENTRY'!M66:M264,SELECTIONS!E3,'DATA ENTRY'!N66:N264,SELECTIONS!E4),0) -> 1 | K27: =J27-0.9 -> 0.1
B28: Site B | C28: =IFERROR(AVERAGEIFS('DATA ENTRY'!E88:E264,'DATA ENTRY'!E88:E264,">0",'DATA ENTRY'!A88:A264,"Site B",'DATA ENTRY'!B88:B264,SELECTIONS!E6,'DATA ENTRY'!C88:C264,SELECTIONS!E3,'DATA ENTRY'!D88:D264,SELECTIONS!E4),0) -> 5.5 | D28: 6 | E28: =C28-D28 -> -0.5 | F28: =IF(C28>=D28,"✓ Staffed","⚠ Gap") -> ⚠ Gap | G28: Downtime | H28: =COUNTIFS('DATA ENTRY'!E66:E264,"Downtime",'DATA ENTRY'!A66:A264,SELECTIONS!E5,'DATA ENTRY'!B66:B264,SELECTIONS!E6,'DATA ENTRY'!M66:M264,SELECTIONS!E3,'DATA ENTRY'!N66:N264,SELECTIONS!E4) -> 0 | I28: =IFERROR(H28/(H27+H28+H29),0) -> 0 | J28: =IFERROR(AVERAGEIFS('DATA ENTRY'!K66:K264,'DATA ENTRY'!E66:E264,"Downtime",'DATA ENTRY'!A66:A264,SELECTIONS!E5,'DATA ENTRY'!B66:B264,SELECTIONS!E6,'DATA ENTRY'!M66:M264,SELECTIONS!E3,'DATA ENTRY'!N66:N264,SELECTIONS!E4),0) -> 0 | K28: =J28-0.9 -> -0.9
B29: Site C | C29: =IFERROR(AVERAGEIFS('DATA ENTRY'!E88:E264,'DATA ENTRY'!E88:E264,">0",'DATA ENTRY'!A88:A264,"Site C",'DATA ENTRY'!B88:B264,SELECTIONS!E6,'DATA ENTRY'!C88:C264,SELECTIONS!E3,'DATA ENTRY'!D88:D264,SELECTIONS!E4),0) -> 5 | D29: 6 | E29: =C29-D29 -> -1 | F29: =IF(C29>=D29,"✓ Staffed","⚠ Gap") -> ⚠ Gap | G29: Due for Repair | H29: =COUNTIFS('DATA ENTRY'!E66:E264,"Due for Repair",'DATA ENTRY'!A66:A264,SELECTIONS!E5,'DATA ENTRY'!B66:B264,SELECTIONS!E6,'DATA ENTRY'!M66:M264,SELECTIONS!E3,'DATA ENTRY'!N66:N264,SELECTIONS!E4) -> 0 | I29: =IFERROR(H29/(H27+H28+H29),0) -> 0 | J29: =IFERROR(AVERAGEIFS('DATA ENTRY'!K66:K264,'DATA ENTRY'!E66:E264,"Due for Repair",'DATA ENTRY'!A66:A264,SELECTIONS!E5,'DATA ENTRY'!B66:B264,SELECTIONS!E6,'DATA ENTRY'!M66:M264,SELECTIONS!E3,'DATA ENTRY'!N66:N264,SELECTIONS!E4),0) -> 0 | K29: =J29-0.9 -> -0.9
B30: Site D | C30: =IFERROR(AVERAGEIFS('DATA ENTRY'!E88:E264,'DATA ENTRY'!E88:E264,">0",'DATA ENTRY'!A88:A264,"Site D",'DATA ENTRY'!B88:B264,SELECTIONS!E6,'DATA ENTRY'!C88:C264,SELECTIONS!E3,'DATA ENTRY'!D88:D264,SELECTIONS!E4),0) -> 5.1666667 | D30: 6 | E30: =C30-D30 -> -0.83333333 | F30: =IF(C30>=D30,"✓ Staffed","⚠ Gap") -> ⚠ Gap
B31: Site E | C31: =IFERROR(AVERAGEIFS('DATA ENTRY'!E88:E264,'DATA ENTRY'!E88:E264,">0",'DATA ENTRY'!A88:A264,"Site E",'DATA ENTRY'!B88:B264,SELECTIONS!E6,'DATA ENTRY'!C88:C264,SELECTIONS!E3,'DATA ENTRY'!D88:D264,SELECTIONS!E4),0) -> 5.1666667 | D31: 6 | E31: =C31-D31 -> -0.83333333 | F31: =IF(C31>=D31,"✓ Staffed","⚠ Gap") -> ⚠ Gap
B32: Site F | C32: =IFERROR(AVERAGEIFS('DATA ENTRY'!E88:E264,'DATA ENTRY'!E88:E264,">0",'DATA ENTRY'!A88:A264,"Site F",'DATA ENTRY'!B88:B264,SELECTIONS!E6,'DATA ENTRY'!C88:C264,SELECTIONS!E3,'DATA ENTRY'!D88:D264,SELECTIONS!E4),0) -> 4.5 | D32: 6 | E32: =C32-D32 -> -1.5 | F32: =IF(C32>=D32,"✓ Staffed","⚠ Gap") -> ⚠ Gap
B33: Site G | C33: =IFERROR(AVERAGEIFS('DATA ENTRY'!E88:E264,'DATA ENTRY'!E88:E264,">0",'DATA ENTRY'!A88:A264,"Site G",'DATA ENTRY'!B88:B264,SELECTIONS!E6,'DATA ENTRY'!C88:C264,SELECTIONS!E3,'DATA ENTRY'!D88:D264,SELECTIONS!E4),0) -> 5 | D33: 6 | E33: =C33-D33 -> -1 | F33: =IF(C33>=D33,"✓ Staffed","⚠ Gap") -> ⚠ Gap
B34: Site H | C34: =IFERROR(AVERAGEIFS('DATA ENTRY'!E88:E264,'DATA ENTRY'!E88:E264,">0",'DATA ENTRY'!A88:A264,"Site H",'DATA ENTRY'!B88:B264,SELECTIONS!E6,'DATA ENTRY'!C88:C264,SELECTIONS!E3,'DATA ENTRY'!D88:D264,SELECTIONS!E4),0) -> 4.6666667 | D34: 6 | E34: =C34-D34 -> -1.3333333 | F34: =IF(C34>=D34,"✓ Staffed","⚠ Gap") -> ⚠ Gap
B35: Site I | C35: =IFERROR(AVERAGEIFS('DATA ENTRY'!E88:E264,'DATA ENTRY'!E88:E264,">0",'DATA ENTRY'!A88:A264,"Site I",'DATA ENTRY'!B88:B264,SELECTIONS!E6,'DATA ENTRY'!C88:C264,SELECTIONS!E3,'DATA ENTRY'!D88:D264,SELECTIONS!E4),0) -> 6.3333333 | D35: 6 | E35: =C35-D35 -> 0.33333333 | F35: =IF(C35>=D35,"✓ Staffed","⚠ Gap") -> ✓ Staffed
A38: Lab Operations Co. · Lab Operations Dashboard · Data is sourced from DATA ENTRY sheet · TAT Target: 90% · Staff Target: 6 per site · Analyzer Availability Target: 90% · Staff Adequacy Target: 100% of departments fully staffed
A50: =SUMIFS('DATA ENTRY'!F6:F500,'DATA ENTRY'!B6:B500,SELECTIONS!E3,'DATA ENTRY'!C6:C500,SELECTIONS!E4,'DATA ENTRY'!D6:D500,SELECTIONS!E5,'DATA ENTRY'!E6:E500,SELECTIONS!E6) -> 12465
A51: =SUMIFS('DATA ENTRY'!G6:G500,'DATA ENTRY'!B6:B500,SELECTIONS!E3,'DATA ENTRY'!C6:C500,SELECTIONS!E4,'DATA ENTRY'!D6:D500,SELECTIONS!E5,'DATA ENTRY'!E6:E500,SELECTIONS!E6) -> 11599
A52: =IFERROR(AVERAGEIFS('DATA ENTRY'!H6:H500,'DATA ENTRY'!H6:H500,">0",'DATA ENTRY'!B6:B500,SELECTIONS!E3,'DATA ENTRY'!C6:C500,SELECTIONS!E4,'DATA ENTRY'!D6:D500,SELECTIONS!E5,'DATA ENTRY'!E6:E500,SELECTIONS!E6),0) -> 0.86777778
A53: =SUMIFS('DATA ENTRY'!G88:G264,'DATA ENTRY'!A88:A264,SELECTIONS!E5,'DATA ENTRY'!B88:B264,SELECTIONS!E6,'DATA ENTRY'!C88:C264,SELECTIONS!E3,'DATA ENTRY'!D88:D264,SELECTIONS!E4) -> -39
A54: =SELECTIONS!E7 -> NO_PREV
A55: =IF(SELECTIONS!E7="NO_PREV",0,SUMIFS('DATA ENTRY'!F6:F500,'DATA ENTRY'!B6:B500,SELECTIONS!E3,'DATA ENTRY'!C6:C500,SELECTIONS!E8,'DATA ENTRY'!D6:D500,SELECTIONS!E5,'DATA ENTRY'!E6:E500,SELECTIONS!E6)) -> 0
A56: =IF(SELECTIONS!E7="NO_PREV",0,SUMIFS('DATA ENTRY'!G6:G500,'DATA ENTRY'!B6:B500,SELECTIONS!E3,'DATA ENTRY'!C6:C500,SELECTIONS!E8,'DATA ENTRY'!D6:D500,SELECTIONS!E5,'DATA ENTRY'!E6:E500,SELECTIONS!E6)) -> 0
A57: =IF(SELECTIONS!E7="NO_PREV",0,IFERROR(AVERAGEIFS('DATA ENTRY'!H6:H500,'DATA ENTRY'!H6:H500,">0",'DATA ENTRY'!B6:B500,SELECTIONS!E3,'DATA ENTRY'!C6:C500,SELECTIONS!E8,'DATA ENTRY'!D6:D500,SELECTIONS!E5,'DATA ENTRY'!E6:E500,SELECTIONS!E6),0)) -> 0
A58: =SUMIFS('DATA ENTRY'!F6:F500,'DATA ENTRY'!B6:B500,SELECTIONS!E3,'DATA ENTRY'!C6:C500,"*",'DATA ENTRY'!D6:D500,SELECTIONS!E5,'DATA ENTRY'!E6:E500,SELECTIONS!E6) -> 12465
...

Sheet DATA ENTRY
A1: LAB OPERATIONS DATA ENTRY
A2: LAB OPERATIONS DATA ENTRY | Section A: Weekly Test Volume & TAT. Section B: Analyzer Register. Section C: Staffing Register. | Add new rows below last entry. Copy formulas in K & L of Section B downward for new analyzers.
A4: SECTION A – Weekly Test Volume & TAT Performance
A5: Year | B5: Month | C5: Week | D5: Site | E5: Department | F5: Tests Run | G5: Unique REQ Numbers | H5: TAT % (Tests meeting target)
A6: 2026 | B6: January | C6: Week 1 | D6: Site A | E6: Chemistry | F6: 137 | G6: 72 | H6: 0.93
A7: 2026 | B7: January | C7: Week 1 | D7: Site A | E7: Serology | F7: 194 | G7: 131 | H7: 0.93
A8: 2026 | B8: January | C8: Week 1 | D8: Site A | E8: Hematology | F8: 359 | G8: 104 | H8: 0.9
A9: 2026 | B9: January | C9: Week 1 | D9: Site A | E9: Cardiac Markers | F9: 95 | G9: 107 | H9: 0.82
A10: 2026 | B10: January | C10: Week 1 | D10: Site A | E10: Endocrinology | F10: 388 | G10: 73 | H10: 0.89
A11: 2026 | B11: January | C11: Week 1 | D11: Site A | E11: Toxicology | F11: 359 | G11: 274 | H11: 0.82
A12: 2026 | B12: January | C12: Week 1 | D12: Site B | E12: Chemistry | F12: 222 | G12: 63 | H12: 0.93
A13: 2026 | B13: January | C13: Week 1 | D13: Site B | E13: Serology | F13: 296 | G13: 234 | H13: 0.84
A14: 2026 | B14: January | C14: Week 1 | D14: Site B | E14: Hematology | F14: 252 | G14: 112 | H14: 0.8
A15: 2026 | B15: January | C15: Week 1 | D15: Site B | E15: Cardiac Markers | F15: 263 | G15: 236 | H15: 0.9
A16: 2026 | B16: January | C16: Week 1 | D16: Site B | E16: Endocrinology | F16: 315 | G16: 334 | H16: 0.8
A17: 2026 | B17: January | C17: Week 1 | D17: Site B | E17: Toxicology | F17: 120 | G17: 342 | H17: 0.84
... A59: 2026 | B59: January | C59: Week 1 | D59: Site I | E59: Toxicology | F59: 288 | G59: 157 | H59: 0.8
A63: SECTION B – Analyzer Register | Fill in Month & Week to match your reporting period. | Fill in Downtime & Repair hours (decimal, e.g. 4.5 = 4h30m) to auto-calculate % Availability | Add more rows as needed — one row per analyzer per period
A64: Site | B64: Department | C64: Analyzer Name | D64: Model/Brand | E64: Status | F64: Last Service Date | G64: Next Service Due | H64: Notes | I64: Downtime Hrs | J64: Repair Hrs | K64: % Availability | L64: Gap vs 90% | M64: Month | N64: Week
A65: ▶ ADD MORE ANALYZERS: Type a new row in this section. Copy formulas in columns K & L from any existing row downward. Fill in Month & Week (cols M & N) to match your reporting period. Availability % = (168 hrs − Downtime hrs − Repair hrs) ÷ 168 hrs per week.
A66: Site A | B66: Chemistry | C66: CHE-Analyzer-01 | D66: Sample Brand | E66: Functional | F66: 2024-01-01 | G66: 2024-07-01 | I66: 0 | J66: 0 | K66: =IFERROR((168-I66-J66)/168,1) -> 1 | L66: =K66-0.9 -> 0.1 | M66: January | N66: Week 1
A67: Site A | B67: Serology | C67: SER-Analyzer-01 | D67: Sample Brand | E67: Functional | F67: 2024-01-01 | G67: 2024-07-01 | I67: 0 | J67: 0 | K67: =IFERROR((168-I67-J67)/168,1) -> 1 | L67: =K67-0.9 -> 0.1 | M67: January | N67: Week 1
A68: Site B | B68: Chemistry | C68: CHE-Analyzer-01 | D68: Sample Brand | E68: Functional | F68: 2024-01-01 | G68: 2024-07-01 | I68: 0 | J68: 0 | K68: =IFERROR((168-I68-J68)/168,1) -> 1 | L68: =K68-0.9 -> 0.1 | M68: January | N68: Week 1
A69: Site B | B69: Serology | C69: SER-Analyzer-01 | D69: Sample Brand | E69: Functional | F69: 2024-01-01 | G69: 2024-07-01 | I69: 0 | J69: 0 | K69: =IFERROR((168-I69-J69)/168,1) -> 1 | L69: =K69-0.9 -> 0.1 | M69: January | N69: Week 1
A70: Site C | B70: Chemistry | C70: CHE-Analyzer-01 | D70: Sample Brand | E70: Functional | F70: 2024-01-01 | G70: 2024-07-01 | I70: 0 | J70: 0 | K70: =IFERROR((168-I70-J70)/168,1) -> 1 | L70: =K70-0.9 -> 0.1 | M70: January | N70: Week 1
A71: Site C | B71: Serology | C71: SER-Analyzer-01 | D71: Sample Brand | E71: Functional | F71: 2024-01-01 | G71: 2024-07-01 | I71: 0 | J71: 0 | K71: =IFERROR((168-I71-J71)/168,1) -> 1 | L71: =K71-0.9 -> 0.1 | M71: January | N71: Week 1
A72: Site D | B72: Chemistry | C72: CHE-Analyzer-01 | D72: Sample Brand | E72: Functional | F72: 2024-01-01 | G72: 2024-07-01 | I72: 0 | J72: 0 | K72: =IFERROR((168-I72-J72)/168,1) -> 1 | L72: =K72-0.9 -> 0.1 | M72: January | N72: Week 1
A73: Site D | B73: Serology | C73: SER-Analyzer-01 | D73: Sample Brand | E73: Functional | F73: 2024-01-01 | G73: 2024-07-01 | I73: 0 | J73: 0 | K73: =IFERROR((168-I73-J73)/168,1) -> 1 | L73: =K73-0.9 -> 0.1 | M73: January | N73: Week 1
A74: Site E | B74: Chemistry | C74: CHE-Analyzer-01 | D74: Sample Brand | E74: Functional | F74: 2024-01-01 | G74: 2024-07-01 | I74: 0 | J74: 0 | K74: =IFERROR((168-I74-J74)/168,1) -> 1 | L74: =K74-0.9 -> 0.1 | M74: January | N74: Week 1
A75: Site E | B75: Serology | C75: SER-Analyzer-01 | D75: Sample Brand | E75: Functional | F75: 2024-01-01 | G75: 2024-07-01 | I75: 0 | J75: 0 | K75: =IFERROR((168-I75-J75)/168,1) -> 1 | L75: =K75-0.9 -> 0.1 | M75: January | N75: Week 1
A76: Site F | B76: Chemistry | C76: CHE-Analyzer-01 | D76: Sample Brand | E76: Functional | F76: 2024-01-01 | G76: 2024-07-01 | I76: 0 | J76: 0 | K76: =IFERROR((168-I76-J76)/168,1) -> 1 | L76: =K76-0.9 -> 0.1 | M76: January | N76: Week 1
A77: Site F | B77: Serology | C77: SER-Analyzer-01 | D77: Sample Brand | E77: Functional | F77: 2024-01-01 | G77: 2024-07-01 | I77: 0 | J77: 0 | K77: =IFERROR((168-I77-J77)/168,1) -> 1 | L77: =K77-0.9 -> 0.1 | M77: January | N77: Week 1
... A83: Site I | B83: Serology | C83: SER-Analyzer-01 | D83: Sample Brand | E83: Functional | F83: 2024-01-01 | G83: 2024-07-01 | I83: 0 | J83: 0 | K83: =IFERROR((168-I83-J83)/168,1) -> 1 | L83: =K83-0.9 -> 0.1 | M83: January | N83: Week 1
A86: SECTION C – Staffing Register
A87: Site | B87: Department | C87: Month | D87: Week | E87: Staff Count (Actual) | F87: Target (6) | G87: Gap
A88: Site A | B88: Chemistry | C88: January | D88: Week 1 | E88: 6 | F88: 6 | G88: =IF(E88="","",E88-F88) -> 0
A89: Site A | B89: Serology | C89: January | D89: Week 1 | E89: 5 | F89: 6 | G89: =IF(E89="","",E89-F89) -> -1
A90: Site A | B90: Hematology | C90: January | D90: Week 1 | E90: 6 | F90: 6 | G90: =IF(E90="","",E90-F90) -> 0
A91: Site A | B91: Cardiac Markers | C91: January | D91: Week 1 | E91: 6 | F91: 6 | G91: =IF(E91="","",E91-F91) -> 0
A92: Site A | B92: Endocrinology | C92: January | D92: Week 1 | E92: 6 | F92: 6 | G92: =IF(E92="","",E92-F92) -> 0
...

Sheet PIVOT DATA
A1: PIVOT DATA – Do not edit this sheet
A2: PURPOSE: This sheet holds pre-computed all-time organisation totals (no filters). The DASHBOARD itself uses SUMIFS/AVERAGEIFS that respond to your SELECTIONS filters. PIVOT DATA is a background reference layer — you don't need to edit it.
A3: Site Summary (all periods) | G3: Dept Summary (all periods) | M3: Analyzer Status Summary
A4: Site | B4: Total Tests | C4: Total REC | D4: Avg TAT% | E4: Staff Gap | G4: Department | H4: Total Tests | I4: Total REC | J4: Avg TAT% | M4: Status | N4: Count
A5: Site A | B5: =SUMIFS('DATA ENTRY'!F6:F500,'DATA ENTRY'!D6:D500,"Site A") -> 1532 | C5: =SUMIFS('DATA ENTRY'!G6:G500,'DATA ENTRY'!D6:D500,"Site A") -> 761 | D5: =IFERROR(AVERAGEIFS('DATA ENTRY'!H6:H500,'DATA ENTRY'!D6:D500,"Site A",'DATA ENTRY'!H6:H500,">0"),0) -> 0.88166667 | E5: =SUMIFS('DATA ENTRY'!G88:G264,'DATA ENTRY'!A88:A264,"Site A") -> 1 | G5: Chemistry | H5: =SUMIFS('DATA ENTRY'!F6:F500,'DATA ENTRY'!E6:E500,"Chemistry") -> 2275 | I5: =SUMIFS('DATA ENTRY'!G6:G500,'DATA ENTRY'!E6:E500,"Chemistry") -> 1561 | J5: =IFERROR(AVERAGEIFS('DATA ENTRY'!H6:H500,'DATA ENTRY'!E6:E500,"Chemistry",'DATA ENTRY'!H6:H500,">0"),0) -> 0.87888889 | M5: Functional | N5: =COUNTIFS('DATA ENTRY'!E66:E264,"Functional") -> 18
A6: Site B | B6: =SUMIFS('DATA ENTRY'!F6:F500,'DATA ENTRY'!D6:D500,"Site B") -> 1468 | C6: =SUMIFS('DATA ENTRY'!G6:G500,'DATA ENTRY'!D6:D500,"Site B") -> 1321 | D6: =IFERROR(AVERAGEIFS('DATA ENTRY'!H6:H500,'DATA ENTRY'!D6:D500,"Site B",'DATA ENTRY'!H6:H500,">0"),0) -> 0.85166667 | E6: =SUMIFS('DATA ENTRY'!G88:G264,'DATA ENTRY'!A88:A264,"Site B") -> -3 | G6: Serology | H6: =SUMIFS('DATA ENTRY'!F6:F500,'DATA ENTRY'!E6:E500,"Serology") -> 1824 | I6: =SUMIFS('DATA ENTRY'!G6:G500,'DATA ENTRY'!E6:E500,"Serology") -> 2096 | J6: =IFERROR(AVERAGEIFS('DATA ENTRY'!H6:H500,'DATA ENTRY'!E6:E500,"Serology",'DATA ENTRY'!H6:H500,">0"),0) -> 0.86222222 | M6: Downtime | N6: =COUNTIFS('DATA ENTRY'!E66:E264,"Downtime") -> 0
A7: Site C | B7: =SUMIFS('DATA ENTRY'!F6:F500,'DATA ENTRY'!D6:D500,"Site C") -> 1232 | C7: =SUMIFS('DATA ENTRY'!G6:G500,'DATA ENTRY'!D6:D500,"Site C") -> 1144 | D7: =IFERROR(AVERAGEIFS('DATA ENTRY'!H6:H500,'DATA ENTRY'!D6:D500,"Site C",'DATA ENTRY'!H6:H500,">0"),0) -> 0.90333333 | E7: =SUMIFS('DATA ENTRY'!G88:G264,'DATA ENTRY'!A88:A264,"Site C") -> -6 | G7: Hematology | H7: =SUMIFS('DATA ENTRY'!F6:F500,'DATA ENTRY'!E6:E500,"Hematology") -> 1717 | I7: =SUMIFS('DATA ENTRY'!G6:G500,'DATA ENTRY'!E6:E500,"Hematology") -> 1744 | J7: =IFERROR(AVERAGEIFS('DATA ENTRY'!H6:H500,'DATA ENTRY'!E6:E500,"Hematology",'DATA ENTRY'!H6:H500,">0"),0) -> 0.88333333 | M7: Due for Repair | N7: =COUNTIFS('DATA ENTRY'!E66:E264,"Due for Repair") -> 0
A8: Site D | B8: =SUMIFS('DATA ENTRY'!F6:F500,'DATA ENTRY'!D6:D500,"Site D") -> 1519 | C8: =SUMIFS('DATA ENTRY'!G6:G500,'DATA ENTRY'!D6:D500,"Site D") -> 1205 | D8: =IFERROR(AVERAGEIFS('DATA ENTRY'!H6:H500,'DATA ENTRY'!D6:D500,"Site D",'DATA ENTRY'!H6:H500,">0"),0) -> 0.85 | E8: =SUMIFS('DATA ENTRY'!G88:G264,'DATA ENTRY'!A88:A264,"Site D") -> -5 | G8: Cardiac Markers | H8: =SUMIFS('DATA ENTRY'!F6:F500,'DATA ENTRY'!E6:E500,"Cardiac Markers") -> 2016 | I8: =SUMIFS('DATA ENTRY'!G6:G500,'DATA ENTRY'!E6:E500,"Cardiac Markers") -> 1828 | J8: =IFERROR(AVERAGEIFS('DATA ENTRY'!H6:H500,'DATA ENTRY'!E6:E500,"Cardiac Markers",'DATA ENTRY'!H6:H500,">0"),0) -> 0.88222222
A9: Site E | B9: =SUMIFS('DATA ENTRY'!F6:F500,'DATA ENTRY'!D6:D500,"Site E") -> 1633 | C9: =SUMIFS('DATA ENTRY'!G6:G500,'DATA ENTRY'!D6:D500,"Site E") -> 1815 | D9: =IFERROR(AVERAGEIFS('DATA ENTRY'!H6:H500,'DATA ENTRY'!D6:D500,"Site E",'DATA ENTRY'!H6:H500,">0"),0) -> 0.86 | E9: =SUMIFS('DATA ENTRY'!G88:G264,'DATA ENTRY'!A88:A264,"Site E") -> -5 | G9: Endocrinology | H9: =SUMIFS('DATA ENTRY'!F6:F500,'DATA ENTRY'!E6:E500,"Endocrinology") -> 2170 | I9: =SUMIFS('DATA ENTRY'!G6:G500,'DATA ENTRY'!E6:E500,"Endocrinology") -> 2213 | J9: =IFERROR(AVERAGEIFS('DATA ENTRY'!H6:H500,'DATA ENTRY'!E6:E500,"Endocrinology",'DATA ENTRY'!H6:H500,">0"),0) -> 0.85555556
A10: Site F | B10: =SUMIFS('DATA ENTRY'!F6:F500,'DATA ENTRY'!D6:D500,"Site F") -> 1148 | C10: =SUMIFS('DATA ENTRY'!G6:G500,'DATA ENTRY'!D6:D500,"Site F") -> 1711 | D10: =IFERROR(AVERAGEIFS('DATA ENTRY'!H6:H500,'DATA ENTRY'!D6:D500,"Site F",'DATA ENTRY'!H6:H500,">0"),0) -> 0.84833333 | E10: =SUMIFS('DATA ENTRY'!G88:G264,'DATA ENTRY'!A88:A264,"Site F") -> -9 | G10: Toxicology | H10: =SUMIFS('DATA ENTRY'!F6:F500,'DATA ENTRY'!E6:E500,"Toxicology") -> 2463 | I10: =SUMIFS('DATA ENTRY'!G6:G500,'DATA ENTRY'!E6:E500,"Toxicology") -> 2157 | J10: =IFERROR(AVERAGEIFS('DATA ENTRY'!H6:H500,'DATA ENTRY'!E6:E500,"Toxicology",'DATA ENTRY'!H6:H500,">0"),0) -> 0.84444444
A11: Site G | B11: =SUMIFS('DATA ENTRY'!F6:F500,'DATA ENTRY'!D6:D500,"Site G") -> 1053 | C11: =SUMIFS('DATA ENTRY'!G6:G500,'DATA ENTRY'!D6:D500,"Site G") -> 1263 | D11: =IFERROR(AVERAGEIFS('DATA ENTRY'!H6:H500,'DATA ENTRY'!D6:D500,"Site G",'DATA ENTRY'!H6:H500,">0"),0) -> 0.89 | E11: =SUMIFS('DATA ENTRY'!G88:G264,'DATA ENTRY'!A88:A264,"Site G") -> -6
A12: Site H | B12: =SUMIFS('DATA ENTRY'!F6:F500,'DATA ENTRY'!D6:D500,"Site H") -> 1341 | C12: =SUMIFS('DATA ENTRY'!G6:G500,'DATA ENTRY'!D6:D500,"Site H") -> 1362 | D12: =IFERROR(AVERAGEIFS('DATA ENTRY'!H6:H500,'DATA ENTRY'!D6:D500,"Site H",'DATA ENTRY'!H6:H500,">0"),0) -> 0.88833333 | E12: =SUMIFS('DATA ENTRY'!G88:G264,'DATA ENTRY'!A88:A264,"Site H") -> -8
A13: Site I | B13: =SUMIFS('DATA ENTRY'!F6:F500,'DATA ENTRY'!D6:D500,"Site I") -> 1539 | C13: =SUMIFS('DATA ENTRY'!G6:G500,'DATA ENTRY'!D6:D500,"Site I") -> 1017 | D13: =IFERROR(AVERAGEIFS('DATA ENTRY'!H6:H500,'DATA ENTRY'!D6:D500,"Site I",'DATA ENTRY'!H6:H500,">0"),0) -> 0.83666667 | E13: =SUMIFS('DATA ENTRY'!G88:G264,'DATA ENTRY'!A88:A264,"Site I") -> 2

Sheet SELECTIONS
A1: FILTER SELECTIONS – Change these cells to filter the Dashboard
A3: Selected Year | B3: 2026 | E3: =IF(B4="All","*",B4) -> January
A4: Selected Month | B4: January | E4: =IF(B5="All","*",B5) -> Week 1
A5: Selected Week | B5: Week 1 | E5: =IF(B6="All Sites","*",B6) -> *
A6: Selected Site | B6: All Sites | E6: =IF(B7="All Departments","*",B7) -> *
A7: Selected Department | B7: All Departments | E7: =IF(B5="Week 1","NO_PREV",IF(B5="Week 2","Week 1",IF(B5="Week 3","Week 2","Week 3"))) -> NO_PREV
E8: =IF(E7="NO_PREV","*",E7) -> *
A9: HOW TO USE:
A10: 1. Change the yellow cells above to filter the DASHBOARD.
A11: 2. Year: Currently 2026 only. Month + Week: drill into any period.
A12: 3. Site: select one site or 'All Sites' for org-wide view.
A13: 4. Department: select one department or 'All Departments'.
A14: 5. Analyzer Status Register on dashboard also filters by Site & Department.
A15: 6. Staff Adequacy KPI: shows % of dept-rows meeting the 6-staff target (filtered). 100% = all staffed.
A16: 7. Analyzer KPI: shows avg % availability vs 90% target (filtered by site & dept).
